Workbook

Sheet Data
A1: Receipt No | B1: Completion Time | C1: Details | D1: Transaction Status | E1: Paid In | F1: Withdrawn | G1: Balance | I1: Total Money IN | J1: Total Money Out | K1: Net | L1: Category | N1: Category | O1: Money Out | P1: Money in | Q1: Investment | R1: Month | S1: Month | T1: Money Out | U1: Money In
A2: UABA93FB4E | B2: 46033.828 | C2: Customer Bundle Purchase to 826915Safaricom Offers by - 2547******109 NAOMI MUREITHI | D2: Completed | F2: 20 | G2: 2620 | I2: =SUM(F:F) -> 161561.22 | J2: =SUM(E:E) -> 165120.13 | K2: =I2-J2 -> -3558.91 | L2: =IF(ISNUMBER(SEARCH("Bundle",C2)),"Bundles",IF(ISNUMBER(SEARCH("Airtime",C2)),"Bundles",IF(ISNUMBER(SEARCH("Merchant",C2)),"Merchant Payment",IF(ISNUMBER(SEARCH("Offnet C2B",C2)),"Merchant Payment",IF(ISNUMBER(SEARCH("Offnet B2C",C2)),"Merchant Payment",IF(ISNUMBER(SEARCH("Customer Payment to Small",C2)),"Merchant Payment",IF(ISNUMBER(SEARCH("Payment to Small Business",C2)),"Merchant Payment",IF(ISNUMBER(SEARCH("Sent to",C2)),"Sent to Person",IF(ISNUMBER(SEARCH("Customer Transfer to",C2)),"Sent to Person",IF(ISNUMBER(SEARCH("Business Payment",C2)),"Money In",IF(ISNUMBER(SEARCH("Funds Received",C2)),"Money In",IF(ISNUMBER(SEARCH("Receive International",C2)),"Money In",IF(ISNUMBER(SEARCH("Send Money Reversal",C2)),"Money In",IF(ISNUMBER(SEARCH("Pay Utility Reversal",C2)),"Money In",IF(ISNUMBER(SEARCH("Customer Transfer",C2)),"Money In",IF(ISNUMBER(SEARCH("Ziidi",C2)),"Investment",IF(ISNUMBER(SEARCH("Nabo",C2)),"Investment",IF(ISNUMBER(SEARCH("Paybill Online",C2)),"Pay Bill",IF(ISNUMBER(SEARCH("Pay Bill",C2)),"Pay Bill",IF(ISNUMBER(SEARCH("Spotify",C2)),"Pay Bill",IF(ISNUMBER(SEARCH("M-Shwari",C2)),"Mshwari",IF(ISNUMBER(SEARCH("Mshwari",C2)),"Mshwari",IF(ISNUMBER(SEARCH("Withdrawal charge",C2)),"Fees",IF(ISNUMBER(SEARCH("Customer Withdrawal",C2)),"Fees",IF(ISNUMBER(SEARCH("charge",C2)),"Fees","Other"))))))))))))))))))))))))) -> Bundles | N2: Bundles | O2: =SUMIF(L:L,"Bundles",F:F) -> 11302 | R2: =TEXT(B2,"MMM YYYY") -> Jan 2026 | S2: 46023 | T2: =SUMIF(R:R,"Jan 2026",F:F) -> 21552 | U2: =SUMIF(R:R,"Jan 2026",E:E) -> 23948 | Z2: =SUM(E2:E10) -> 0
A3: UABA93HFN9 | B3: 46033.828 | C3: Customer Payment to Small Business to - 2541******638 LEAH WAMBUGU | D3: Completed | F3: 40 | G3: 2580 | K3: =I3-J3 -> 0 | L3: =IF(ISNUMBER(SEARCH("Bundle",C3)),"Bundles",IF(ISNUMBER(SEARCH("Airtime",C3)),"Bundles",IF(ISNUMBER(SEARCH("Merchant",C3)),"Merchant Payment",IF(ISNUMBER(SEARCH("Offnet C2B",C3)),"Merchant Payment",IF(ISNUMBER(SEARCH("Offnet B2C",C3)),"Merchant Payment",IF(ISNUMBER(SEARCH("Customer Payment to Small",C3)),"Merchant Payment",IF(ISNUMBER(SEARCH("Payment to Small Business",C3)),"Merchant Payment",IF(ISNUMBER(SEARCH("Sent to",C3)),"Sent to Person",IF(ISNUMBER(SEARCH("Customer Transfer to",C3)),"Sent to Person",IF(ISNUMBER(SEARCH("Business Payment",C3)),"Money In",IF(ISNUMBER(SEARCH("Funds Received",C3)),"Money In",IF(ISNUMBER(SEARCH("Receive International",C3)),"Money In",IF(ISNUMBER(SEARCH("Send Money Reversal",C3)),"Money In",IF(ISNUMBER(SEARCH("Pay Utility Reversal",C3)),"Money In",IF(ISNUMBER(SEARCH("Customer Transfer",C3)),"Money In",IF(ISNUMBER(SEARCH("Ziidi",C3)),"Investment",IF(ISNUMBER(SEARCH("Nabo",C3)),"Investment",IF(ISNUMBER(SEARCH("Paybill Online",C3)),"Pay Bill",IF(ISNUMBER(SEARCH("Pay Bill",C3)),"Pay Bill",IF(ISNUMBER(SEARCH("Spotify",C3)),"Pay Bill",IF(ISNUMBER(SEARCH("M-Shwari",C3)),"Mshwari",IF(ISNUMBER(SEARCH("Mshwari",C3)),"Mshwari",IF(ISNUMBER(SEARCH("Withdrawal charge",C3)),"Fees",IF(ISNUMBER(SEARCH("Customer Withdrawal",C3)),"Fees",IF(ISNUMBER(SEARCH("charge",C3)),"Fees","Other"))))))))))))))))))))))))) -> Merchant Payment | N3: Merchant Payment | O3: =SUMIF(L:L,"Merchant Payment",F:F) -> 36852 | R3: =TEXT(B2,"MMM YYYY") -> Jan 2026 | S3: 46054 | T3: =SUMIF(R:R,"Feb 2026",F:F) -> 47979 | U3: =SUMIF(R:R,"Feb 2026",E:E) -> 49631
A4: UABA93HFOK | B4: 2026-01-11 19:53:39 | C4: Customer Payment to Small Business to - 2547******122 SAMWEL OKUMBOH | D4: Completed | F4: 80 | G4: 2500 | L4: =IF(ISNUMBER(SEARCH("Bundle",C4)),"Bundles",IF(ISNUMBER(SEARCH("Airtime",C4)),"Bundles",IF(ISNUMBER(SEARCH("Merchant",C4)),"Merchant Payment",IF(ISNUMBER(SEARCH("Offnet C2B",C4)),"Merchant Payment",IF(ISNUMBER(SEARCH("Offnet B2C",C4)),"Merchant Payment",IF(ISNUMBER(SEARCH("Customer Payment to Small",C4)),"Merchant Payment",IF(ISNUMBER(SEARCH("Payment to Small Business",C4)),"Merchant Payment",IF(ISNUMBER(SEARCH("Sent to",C4)),"Sent to Person",IF(ISNUMBER(SEARCH("Customer Transfer to",C4)),"Sent to Person",IF(ISNUMBER(SEARCH("Business Payment",C4)),"Money In",IF(ISNUMBER(SEARCH("Funds Received",C4)),"Money In",IF(ISNUMBER(SEARCH("Receive International",C4)),"Money In",IF(ISNUMBER(SEARCH("Send Money Reversal",C4)),"Money In",IF(ISNUMBER(SEARCH("Pay Utility Reversal",C4)),"Money In",IF(ISNUMBER(SEARCH("Customer Transfer",C4)),"Money In",IF(ISNUMBER(SEARCH("Ziidi",C4)),"Investment",IF(ISNUMBER(SEARCH("Nabo",C4)),"Investment",IF(ISNUMBER(SEARCH("Paybill Online",C4)),"Pay Bill",IF(ISNUMBER(SEARCH("Pay Bill",C4)),"Pay Bill",IF(ISNUMBER(SEARCH("Spotify",C4)),"Pay Bill",IF(ISNUMBER(SEARCH("M-Shwari",C4)),"Mshwari",IF(ISNUMBER(SEARCH("Mshwari",C4)),"Mshwari",IF(ISNUMBER(SEARCH("Withdrawal charge",C4)),"Fees",IF(ISNUMBER(SEARCH("Customer Withdrawal",C4)),"Fees",IF(ISNUMBER(SEARCH("charge",C4)),"Fees","Other"))))))))))))))))))))))))) -> Merchant Payment | N4: Paybill | O4: =SUMIF(L:L,"Pay Bill",F:F) -> 16212 | R4: =TEXT(B2,"MMM YYYY") -> Jan 2026 | S4: 46082 | T4: =SUMIF(R:R,"Mar 2026",F:F) -> 35418.22 | U4: =SUMIF(R:R,"Mar 2026",E:E) -> 35435
A5: UACA93I2I5 | B5: 2026-01-12 07:15:58 | C5: Customer Bundle Purchase to 4093441SAFARICOM DATA BUNDLES by - 2547******109 NAOMI MUREITHI | D5: Completed | F5: 20 | G5: 2480 | L5: =IF(ISNUMBER(SEARCH("Bundle",C5)),"Bundles",IF(ISNUMBER(SEARCH("Airtime",C5)),"Bundles",IF(ISNUMBER(SEARCH("Merchant",C5)),"Merchant Payment",IF(ISNUMBER(SEARCH("Offnet C2B",C5)),"Merchant Payment",IF(ISNUMBER(SEARCH("Offnet B2C",C5)),"Merchant Payment",IF(ISNUMBER(SEARCH("Customer Payment to Small",C5)),"Merchant Payment",IF(ISNUMBER(SEARCH("Payment to Small Business",C5)),"Merchant Payment",IF(ISNUMBER(SEARCH("Sent to",C5)),"Sent to Person",IF(ISNUMBER(SEARCH("Customer Transfer to",C5)),"Sent to Person",IF(ISNUMBER(SEARCH("Business Payment",C5)),"Money In",IF(ISNUMBER(SEARCH("Funds Received",C5)),"Money In",IF(ISNUMBER(SEARCH("Receive International",C5)),"Money In",IF(ISNUMBER(SEARCH("Send Money Reversal",C5)),"Money In",IF(ISNUMBER(SEARCH("Pay Utility Reversal",C5)),"Money In",IF(ISNUMBER(SEARCH("Customer Transfer",C5)),"Money In",IF(ISNUMBER(SEARCH("Ziidi",C5)),"Investment",IF(ISNUMBER(SEARCH("Nabo",C5)),"Investment",IF(ISNUMBER(SEARCH("Paybill Online",C5)),"Pay Bill",IF(ISNUMBER(SEARCH("Pay Bill",C5)),"Pay Bill",IF(ISNUMBER(SEARCH("Spotify",C5)),"Pay Bill",IF(ISNUMBER(SEARCH("M-Shwari",C5)),"Mshwari",IF(ISNUMBER(SEARCH("Mshwari",C5)),"Mshwari",IF(ISNUMBER(SEARCH("Withdrawal charge",C5)),"Fees",IF(ISNUMBER(SEARCH("Customer Withdrawal",C5)),"Fees",IF(ISNUMBER(SEARCH("charge",C5)),"Fees","Other"))))))))))))))))))))))))) -> Bundles | N5: Money In | P5: =SUMIF(L:L,"Money In",E:E) -> 117178 | R5: =TEXT(B2,"MMM YYYY") -> Jan 2026 | S5: 46113 | T5: =SUMIF(R:R,"Apr 2026",F:F) -> 31669 | U5: =SUMIF(R:R,"Apr 2026",E:E) -> 31579
A6: UACA93IINZ | B6: 2026-01-12 09:27:39 | C6: Customer Bundle Purchase to 4093441SAFARICOM DATA BUNDLES by - 2547******109 NAOMI MUREITHI | D6: Completed | F6: 10 | G6: 2470 | L6: =IF(ISNUMBER(SEARCH("Bundle",C6)),"Bundles",IF(ISNUMBER(SEARCH("Airtime",C6)),"Bundles",IF(ISNUMBER(SEARCH("Merchant",C6)),"Merchant Payment",IF(ISNUMBER(SEARCH("Offnet C2B",C6)),"Merchant Payment",IF(ISNUMBER(SEARCH("Offnet B2C",C6)),"Merchant Payment",IF(ISNUMBER(SEARCH("Customer Payment to Small",C6)),"Merchant Payment",IF(ISNUMBER(SEARCH("Payment to Small Business",C6)),"Merchant Payment",IF(ISNUMBER(SEARCH("Sent to",C6)),"Sent to Person",IF(ISNUMBER(SEARCH("Customer Transfer to",C6)),"Sent to Person",IF(ISNUMBER(SEARCH("Business Payment",C6)),"Money In",IF(ISNUMBER(SEARCH("Funds Received",C6)),"Money In",IF(ISNUMBER(SEARCH("Receive International",C6)),"Money In",IF(ISNUMBER(SEARCH("Send Money Reversal",C6)),"Money In",IF(ISNUMBER(SEARCH("Pay Utility Reversal",C6)),"Money In",IF(ISNUMBER(SEARCH("Customer Transfer",C6)),"Money In",IF(ISNUMBER(SEARCH("Ziidi",C6)),"Investment",IF(ISNUMBER(SEARCH("Nabo",C6)),"Investment",IF(ISNUMBER(SEARCH("Paybill Online",C6)),"Pay Bill",IF(ISNUMBER(SEARCH("Pay Bill",C6)),"Pay Bill",IF(ISNUMBER(SEARCH("Spotify",C6)),"Pay Bill",IF(ISNUMBER(SEARCH("M-Shwari",C6)),"Mshwari",IF(ISNUMBER(SEARCH("Mshwari",C6)),"Mshwari",IF(ISNUMBER(SEARCH("Withdrawal charge",C6)),"Fees",IF(ISNUMBER(SEARCH("Customer Withdrawal",C6)),"Fees",IF(ISNUMBER(SEARCH("charge",C6)),"Fees","Other"))))))))))))))))))))))))) -> Bundles | N6: Fees | O6: =SUMIF(L:L,"Fees",F:F) -> 1780 | R6: =TEXT(B2,"MMM YYYY") -> Jan 2026 | S6: 46143 | T6: =SUMIF(R:R,"May 2026",F:F) -> 22867 | U6: =SUMIF(R:R,"May 2026",E:E) -> 23720
A7: UACA93IOER | B7: 2026-01-12 10:33:10 | C7: Customer Bundle Purchase to 4093441SAFARICOM DATA BUNDLES by - 2547******109 NAOMI MUREITHI | D7: Completed | F7: 10 | G7: 2460 | L7: =IF(ISNUMBER(SEARCH("Bundle",C7)),"Bundles",IF(ISNUMBER(SEARCH("Airtime",C7)),"Bundles",IF(ISNUMBER(SEARCH("Merchant",C7)),"Merchant Payment",IF(ISNUMBER(SEARCH("Offnet C2B",C7)),"Merchant Payment",IF(ISNUMBER(SEARCH("Offnet B2C",C7)),"Merchant Payment",IF(ISNUMBER(SEARCH("Customer Payment to Small",C7)),"Merchant Payment",IF(ISNUMBER(SEARCH("Payment to Small Business",C7)),"Merchant Payment",IF(ISNUMBER(SEARCH("Sent to",C7)),"Sent to Person",IF(ISNUMBER(SEARCH("Customer Transfer to",C7)),"Sent to Person",IF(ISNUMBER(SEARCH("Business Payment",C7)),"Money In",IF(ISNUMBER(SEARCH("Funds Received",C7)),"Money In",IF(ISNUMBER(SEARCH("Receive International",C7)),"Money In",IF(ISNUMBER(SEARCH("Send Money Reversal",C7)),"Money In",IF(ISNUMBER(SEARCH("Pay Utility Reversal",C7)),"Money In",IF(ISNUMBER(SEARCH("Customer Transfer",C7)),"Money In",IF(ISNUMBER(SEARCH("Ziidi",C7)),"Investment",IF(ISNUMBER(SEARCH("Nabo",C7)),"Investment",IF(ISNUMBER(SEARCH("Paybill Online",C7)),"Pay Bill",IF(ISNUMBER(SEARCH("Pay Bill",C7)),"Pay Bill",IF(ISNUMBER(SEARCH("Spotify",C7)),"Pay Bill",IF(ISNUMBER(SEARCH("M-Shwari",C7)),"Mshwari",IF(ISNUMBER(SEARCH("Mshwari",C7)),"Mshwari",IF(ISNUMBER(SEARCH("Withdrawal charge",C7)),"Fees",IF(ISNUMBER(SEARCH("Customer Withdrawal",C7)),"Fees",IF(ISNUMBER(SEARCH("charge",C7)),"Fees","Other"))))))))))))))))))))))))) -> Bundles | N7: Sent to Person | O7: =SUMIF(L:L,"Sent to Person",F:F) -> 25295 | R7: =TEXT(B2,"MMM YYYY") -> Jan 2026 | S7: Total | T7: =SUM(T2:T6) -> 159485.22 | U7: =SUM(U2:U6) -> 164313
A8: UACA93JEPJ | B8: 2026-01-12 13:56:16 | C8: Customer Bundle Purchase to 826915Safaricom Offers by - 2547******109 NAOMI MUREITHI | D8: Completed | F8: 20 | G8: 2440 | L8: =IF(ISNUMBER(SEARCH("Bundle",C8)),"Bundles",IF(ISNUMBER(SEARCH("Airtime",C8)),"Bundles",IF(ISNUMBER(SEARCH("Merchant",C8)),"Merchant Payment",IF(ISNUMBER(SEARCH("Offnet C2B",C8)),"Merchant Payment",IF(ISNUMBER(SEARCH("Offnet B2C",C8)),"Merchant Payment",IF(ISNUMBER(SEARCH("Customer Payment to Small",C8)),"Merchant Payment",IF(ISNUMBER(SEARCH("Payment to Small Business",C8)),"Merchant Payment",IF(ISNUMBER(SEARCH("Sent to",C8)),"Sent to Person",IF(ISNUMBER(SEARCH("Customer Transfer to",C8)),"Sent to Person",IF(ISNUMBER(SEARCH("Business Payment",C8)),"Money In",IF(ISNUMBER(SEARCH("Funds Received",C8)),"Money In",IF(ISNUMBER(SEARCH("Receive International",C8)),"Money In",IF(ISNUMBER(SEARCH("Send Money Reversal",C8)),"Money In",IF(ISNUMBER(SEARCH("Pay Utility Reversal",C8)),"Money In",IF(ISNUMBER(SEARCH("Customer Transfer",C8)),"Money In",IF(ISNUMBER(SEARCH("Ziidi",C8)),"Investment",IF(ISNUMBER(SEARCH("Nabo",C8)),"Investment",IF(ISNUMBER(SEARCH("Paybill Online",C8)),"Pay Bill",IF(ISNUMBER(SEARCH("Pay Bill",C8)),"Pay Bill",IF(ISNUMBER(SEARCH("Spotify",C8)),"Pay Bill",IF(ISNUMBER(SEARCH("M-Shwari",C8)),"Mshwari",IF(ISNUMBER(SEARCH("Mshwari",C8)),"Mshwari",IF(ISNUMBER(SEARCH("Withdrawal charge",C8)),"Fees",IF(ISNUMBER(SEARCH("Customer Withdrawal",C8)),"Fees",IF(ISNUMBER(SEARCH("charge",C8)),"Fees","Other"))))))))))))))))))))))))) -> Bundles | N8: M-Shwari | O8: =SUMIF(L:L,"Mshwari",F:F) -> 42300 | P8: =SUMIF(L:L,"Mshwari",E:E) -> 47895 | R8: =TEXT(B2,"MMM YYYY") -> Jan 2026
A9: UACA93JGAR | B9: 2026-01-12 13:59:22 | C9: Customer Bundle Purchase to 4093441SAFARICOM DATA BUNDLES by - 2547******109 NAOMI MUREITHI | D9: Completed | F9: 30 | G9: 2410 | L9: =IF(ISNUMBER(SEARCH("Bundle",C9)),"Bundles",IF(ISNUMBER(SEARCH("Airtime",C9)),"Bundles",IF(ISNUMBER(SEARCH("Merchant",C9)),"Merchant Payment",IF(ISNUMBER(SEARCH("Offnet C2B",C9)),"Merchant Payment",IF(ISNUMBER(SEARCH("Offnet B2C",C9)),"Merchant Payment",IF(ISNUMBER(SEARCH("Customer Payment to Small",C9)),"Merchant Payment",IF(ISNUMBER(SEARCH("Payment to Small Business",C9)),"Merchant Payment",IF(ISNUMBER(SEARCH("Sent to",C9)),"Sent to Person",IF(ISNUMBER(SEARCH("Customer Transfer to",C9)),"Sent to Person",IF(ISNUMBER(SEARCH("Business Payment",C9)),"Money In",IF(ISNUMBER(SEARCH("Funds Received",C9)),"Money In",IF(ISNUMBER(SEARCH("Receive International",C9)),"Money In",IF(ISNUMBER(SEARCH("Send Money Reversal",C9)),"Money In",IF(ISNUMBER(SEARCH("Pay Utility Reversal",C9)),"Money In",IF(ISNUMBER(SEARCH("Customer Transfer",C9)),"Money In",IF(ISNUMBER(SEARCH("Ziidi",C9)),"Investment",IF(ISNUMBER(SEARCH("Nabo",C9)),"Investment",IF(ISNUMBER(SEARCH("Paybill Online",C9)),"Pay Bill",IF(ISNUMBER(SEARCH("Pay Bill",C9)),"Pay Bill",IF(ISNUMBER(SEARCH("Spotify",C9)),"Pay Bill",IF(ISNUMBER(SEARCH("M-Shwari",C9)),"Mshwari",IF(ISNUMBER(SEARCH("Mshwari",C9)),"Mshwari",IF(ISNUMBER(SEARCH("Withdrawal charge",C9)),"Fees",IF(ISNUMBER(SEARCH("Customer Withdrawal",C9)),"Fees",IF(ISNUMBER(SEARCH("charge",C9)),"Fees","Other"))))))))))))))))))))))))) -> Bundles | N9: Investment | O9: Asset | Q9: 27313 | R9: =TEXT(B2,"MMM YYYY") -> Jan 2026
A10: UACA93K4N4 | B10: 2026-01-12 18:17:34 | C10: Merchant Payment to 6682492 - OBI BAKERY | D10: Completed | F10: 90 | G10: 2320 | L10: =IF(ISNUMBER(SEARCH("Bundle",C10)),"Bundles",IF(ISNUMBER(SEARCH("Airtime",C10)),"Bundles",IF(ISNUMBER(SEARCH("Merchant",C10)),"Merchant Payment",IF(ISNUMBER(SEARCH("Offnet C2B",C10)),"Merchant Payment",IF(ISNUMBER(SEARCH("Offnet B2C",C10)),"Merchant Payment",IF(ISNUMBER(SEARCH("Customer Payment to Small",C10)),"Merchant Payment",IF(ISNUMBER(SEARCH("Payment to Small Business",C10)),"Merchant Payment",IF(ISNUMBER(SEARCH("Sent to",C10)),"Sent to Person",IF(ISNUMBER(SEARCH("Customer Transfer to",C10)),"Sent to Person",IF(ISNUMBER(SEARCH("Business Payment",C10)),"Money In",IF(ISNUMBER(SEARCH("Funds Received",C10)),"Money In",IF(ISNUMBER(SEARCH("Receive International",C10)),"Money In",IF(ISNUMBER(SEARCH("Send Money Reversal",C10)),"Money In",IF(ISNUMBER(SEARCH("Pay Utility Reversal",C10)),"Money In",IF(ISNUMBER(SEARCH("Customer Transfer",C10)),"Money In",IF(ISNUMBER(SEARCH("Ziidi",C10)),"Investment",IF(ISNUMBER(SEARCH("Nabo",C10)),"Investment",IF(ISNUMBER(SEARCH("Paybill Online",C10)),"Pay Bill",IF(ISNUMBER(SEARCH("Pay Bill",C10)),"Pay Bill",IF(ISNUMBER(SEARCH("Spotify",C10)),"Pay Bill",IF(ISNUMBER(SEARCH("M-Shwari",C10)),"Mshwari",IF(ISNUMBER(SEARCH("Mshwari",C10)),"Mshwari",IF(ISNUMBER(SEARCH("Withdrawal charge",C10)),"Fees",IF(ISNUMBER(SEARCH("Customer Withdrawal",C10)),"Fees",IF(ISNUMBER(SEARCH("charge",C10)),"Fees","Other"))))))))))))))))))))))))) -> Merchant Payment | N10: Other | O10: =SUMIF(L:L,"Other",F:F) -> 0 | R10: =TEXT(B2,"MMM YYYY") -> Jan 2026
A11: UACA93K9LG | B11: 2026-01-12 18:20:35 | C11: Merchant Payment to 7327328 - Vincent Otieno | D11: Completed | F11: 100 | G11: 2220 | L11: =IF(ISNUMBER(SEARCH("Bundle",C11)),"Bundles",IF(ISNUMBER(SEARCH("Airtime",C11)),"Bundles",IF(ISNUMBER(SEARCH("Merchant",C11)),"Merchant Payment",IF(ISNUMBER(SEARCH("Offnet C2B",C11)),"Merchant Payment",IF(ISNUMBER(SEARCH("Offnet B2C",C11)),"Merchant Payment",IF(ISNUMBER(SEARCH("Customer Payment to Small",C11)),"Merchant Payment",IF(ISNUMBER(SEARCH("Payment to Small Business",C11)),"Merchant Payment",IF(ISNUMBER(SEARCH("Sent to",C11)),"Sent to Person",IF(ISNUMBER(SEARCH("Customer Transfer to",C11)),"Sent to Person",IF(ISNUMBER(SEARCH("Business Payment",C11)),"Money In",IF(ISNUMBER(SEARCH("Funds Received",C11)),"Money In",IF(ISNUMBER(SEARCH("Receive International",C11)),"Money In",IF(ISNUMBER(SEARCH("Send Money Reversal",C11)),"Money In",IF(ISNUMBER(SEARCH("Pay Utility Reversal",C11)),"Money In",IF(ISNUMBER(SEARCH("Customer Transfer",C11)),"Money In",IF(ISNUMBER(SEARCH("Ziidi",C11)),"Investment",IF(ISNUMBER(SEARCH("Nabo",C11)),"Investment",IF(ISNUMBER(SEARCH("Paybill Online",C11)),"Pay Bill",IF(ISNUMBER(SEARCH("Pay Bill",C11)),"Pay Bill",IF(ISNUMBER(SEARCH("Spotify",C11)),"Pay Bill",IF(ISNUMBER(SEARCH("M-Shwari",C11)),"Mshwari",IF(ISNUMBER(SEARCH("Mshwari",C11)),"Mshwari",IF(ISNUMBER(SEARCH("Withdrawal charge",C11)),"Fees",IF(ISNUMBER(SEARCH("Customer Withdrawal",C11)),"Fees",IF(ISNUMBER(SEARCH("charge",C11)),"Fees","Other"))))))))))))))))))))))))) -> Merchant Payment | N11: TOTAL | O11: =SUM(O2:O10) -> 133741 | P11: =SUM(P2:P9) -> 165073 | Q11: 27313 | R11: =TEXT(B2,"MMM YYYY") -> Jan 2026
A12: UACA93K8JX | B12: 2026-01-12 18:38:18 | C12: Customer Bundle Purchase to 4093441SAFARICOM DATA BUNDLES by - 2547******109 NAOMI MUREITHI | D12: Completed | F12: 10 | G12: 2210 | L12: =IF(ISNUMBER(SEARCH("Bundle",C12)),"Bundles",IF(ISNUMBER(SEARCH("Airtime",C12)),"Bundles",IF(ISNUMBER(SEARCH("Merchant",C12)),"Merchant Payment",IF(ISNUMBER(SEARCH("Offnet C2B",C12)),"Merchant Payment",IF(ISNUMBER(SEARCH("Offnet B2C",C12)),"Merchant Payment",IF(ISNUMBER(SEARCH("Customer Payment to Small",C12)),"Merchant Payment",IF(ISNUMBER(SEARCH("Payment to Small Business",C12)),"Merchant Payment",IF(ISNUMBER(SEARCH("Sent to",C12)),"Sent to Person",IF(ISNUMBER(SEARCH("Customer Transfer to",C12)),"Sent to Person",IF(ISNUMBER(SEARCH("Business Payment",C12)),"Money In",IF(ISNUMBER(SEARCH("Funds Received",C12)),"Money In",IF(ISNUMBER(SEARCH("Receive International",C12)),"Money In",IF(ISNUMBER(SEARCH("Send Money Reversal",C12)),"Money In",IF(ISNUMBER(SEARCH("Pay Utility Reversal",C12)),"Money In",IF(ISNUMBER(SEARCH("Customer Transfer",C12)),"Money In",IF(ISNUMBER(SEARCH("Ziidi",C12)),"Investment",IF(ISNUMBER(SEARCH("Nabo",C12)),"Investment",IF(ISNUMBER(SEARCH("Paybill Online",C12)),"Pay Bill",IF(ISNUMBER(SEARCH("Pay Bill",C12)),"Pay Bill",IF(ISNUMBER(SEARCH("Spotify",C12)),"Pay Bill",IF(ISNUMBER(SEARCH("M-Shwari",C12)),"Mshwari",IF(ISNUMBER(SEARCH("Mshwari",C12)),"Mshwari",IF(ISNUMBER(SEARCH("Withdrawal charge",C12)),"Fees",IF(ISNUMBER(SEARCH("Customer Withdrawal",C12)),"Fees",IF(ISNUMBER(SEARCH("charge",C12)),"Fees","Other"))))))))))))))))))))))))) -> Bundles | R12: =TEXT(B2,"MMM YYYY") -> Jan 2026
A13: UACA93KYWH | B13: 2026-01-12 20:51:15 | C13: Customer Bundle Purchase to 4093441SAFARICOM DATA BUNDLES by - 2547******109 NAOMI MUREITHI | D13: Completed | F13: 30 | G13: 2180 | L13: =IF(ISNUMBER(SEARCH("Bundle",C13)),"Bundles",IF(ISNUMBER(SEARCH("Airtime",C13)),"Bundles",IF(ISNUMBER(SEARCH("Merchant",C13)),"Merchant Payment",IF(ISNUMBER(SEARCH("Offnet C2B",C13)),"Merchant Payment",IF(ISNUMBER(SEARCH("Offnet B2C",C13)),"Merchant Payment",IF(ISNUMBER(SEARCH("Customer Payment to Small",C13)),"Merchant Payment",IF(ISNUMBER(SEARCH("Payment to Small Business",C13)),"Merchant Payment",IF(ISNUMBER(SEARCH("Sent to",C13)),"Sent to Person",IF(ISNUMBER(SEARCH("Customer Transfer to",C13)),"Sent to Person",IF(ISNUMBER(SEARCH("Business Payment",C13)),"Money In",IF(ISNUMBER(SEARCH("Funds Received",C13)),"Money In",IF(ISNUMBER(SEARCH("Receive International",C13)),"Money In",IF(ISNUMBER(SEARCH("Send Money Reversal",C13)),"Money In",IF(ISNUMBER(SEARCH("Pay Utility Reversal",C13)),"Money In",IF(ISNUMBER(SEARCH("Customer Transfer",C13)),"Money In",IF(ISNUMBER(SEARCH("Ziidi",C13)),"Investment",IF(ISNUMBER(SEARCH("Nabo",C13)),"Investment",IF(ISNUMBER(SEARCH("Paybill Online",C13)),"Pay Bill",IF(ISNUMBER(SEARCH("Pay Bill",C13)),"Pay Bill",IF(ISNUMBER(SEARCH("Spotify",C13)),"Pay Bill",IF(ISNUMBER(SEARCH("M-Shwari",C13)),"Mshwari",IF(ISNUMBER(SEARCH("Mshwari",C13)),"Mshwari",IF(ISNUMBER(SEARCH("Withdrawal charge",C13)),"Fees",IF(ISNUMBER(SEARCH("Customer Withdrawal",C13)),"Fees",IF(ISNUMBER(SEARCH("charge",C13)),"Fees","Other"))))))))))))))))))))))))) -> Bundles | R13: =TEXT(B2,"MMM YYYY") -> Jan 2026
A14: UADA93LBQE | B14: 2026-01-13 03:14:01 | C14: Merchant Payment to 7225027 - NAKURU DRIVE INN HOTEL | D14: Completed | F14: 80 | G14: 2100 | L14: =IF(ISNUMBER(SEARCH("Bundle",C14)),"Bundles",IF(ISNUMBER(SEARCH("Airtime",C14)),"Bundles",IF(ISNUMBER(SEARCH("Merchant",C14)),"Merchant Payment",IF(ISNUMBER(SEARCH("Offnet C2B",C14)),"Merchant Payment",IF(ISNUMBER(SEARCH("Offnet B2C",C14)),"Merchant Payment",IF(ISNUMBER(SEARCH("Customer Payment to Small",C14)),"Merchant Payment",IF(ISNUMBER(SEARCH("Payment to Small Business",C14)),"Merchant Payment",IF(ISNUMBER(SEARCH("Sent to",C14)),"Sent to Person",IF(ISNUMBER(SEARCH("Customer Transfer to",C14)),"Sent to Person",IF(ISNUMBER(SEARCH("Business Payment",C14)),"Money In",IF(ISNUMBER(SEARCH("Funds Received",C14)),"Money In",IF(ISNUMBER(SEARCH("Receive International",C14)),"Money In",IF(ISNUMBER(SEARCH("Send Money Reversal",C14)),"Money In",IF(ISNUMBER(SEARCH("Pay Utility Reversal",C14)),"Money In",IF(ISNUMBER(SEARCH("Customer Transfer",C14)),"Money In",IF(ISNUMBER(SEARCH("Ziidi",C14)),"Investment",IF(ISNUMBER(SEARCH("Nabo",C14)),"Investment",IF(ISNUMBER(SEARCH("Paybill Online",C14)),"Pay Bill",IF(ISNUMBER(SEARCH("Pay Bill",C14)),"Pay Bill",IF(ISNUMBER(SEARCH("Spotify",C14)),"Pay Bill",IF(ISNUMBER(SEARCH("M-Shwari",C14)),"Mshwari",IF(ISNUMBER(SEARCH("Mshwari",C14)),"Mshwari",IF(ISNUMBER(SEARCH("Withdrawal charge",C14)),"Fees",IF(ISNUMBER(SEARCH("Customer Withdrawal",C14)),"Fees",IF(ISNUMBER(SEARCH("charge",C14)),"Fees","Other"))))))))))))))))))))))))) -> Merchant Payment | R14: =TEXT(B2,"MMM YYYY") -> Jan 2026
A15: UADA93LRMF | B15: 2026-01-13 08:45:54 | C15: Customer Bundle Purchase to 4093441SAFARICOM DATA BUNDLES by - 2547******109 NAOMI MUREITHI | D15: Completed | F15: 10 | G15: 2090 | L15: =IF(ISNUMBER(SEARCH("Bundle",C15)),"Bundles",IF(ISNUMBER(SEARCH("Airtime",C15)),"Bundles",IF(ISNUMBER(SEARCH("Merchant",C15)),"Merchant Payment",IF(ISNUMBER(SEARCH("Offnet C2B",C15)),"Merchant Payment",IF(ISNUMBER(SEARCH("Offnet B2C",C15)),"Merchant Payment",IF(ISNUMBER(SEARCH("Customer Payment to Small",C15)),"Merchant Payment",IF(ISNUMBER(SEARCH("Payment to Small Business",C15)),"Merchant Payment",IF(ISNUMBER(SEARCH("Sent to",C15)),"Sent to Person",IF(ISNUMBER(SEARCH("Customer Transfer to",C15)),"Sent to Person",IF(ISNUMBER(SEARCH("Business Payment",C15)),"Money In",IF(ISNUMBER(SEARCH("Funds Received",C15)),"Money In",IF(ISNUMBER(SEARCH("Receive International",C15)),"Money In",IF(ISNUMBER(SEARCH("Send Money Reversal",C15)),"Money In",IF(ISNUMBER(SEARCH("Pay Utility Reversal",C15)),"Money In",IF(ISNUMBER(SEARCH("Customer Transfer",C15)),"Money In",IF(ISNUMBER(SEARCH("Ziidi",C15)),"Investment",IF(ISNUMBER(SEARCH("Nabo",C15)),"Investment",IF(ISNUMBER(SEARCH("Paybill Online",C15)),"Pay Bill",IF(ISNUMBER(SEARCH("Pay Bill",C15)),"Pay Bill",IF(ISNUMBER(SEARCH("Spotify",C15)),"Pay Bill",IF(ISNUMBER(SEARCH("M-Shwari",C15)),"Mshwari",IF(ISNUMBER(SEARCH("Mshwari",C15)),"Mshwari",IF(ISNUMBER(SEARCH("Withdrawal charge",C15)),"Fees",IF(ISNUMBER(SEARCH("Customer Withdrawal",C15)),"Fees",IF(ISNUMBER(SEARCH("charge",C15)),"Fees","Other"))))))))))))))))))))))))) -> Bundles | R15: =TEXT(B2,"MMM YYYY") -> Jan 2026
A16: UADA93LQ7A | B16: 2026-01-13 08:47:08 | C16: Customer Bundle Purchase to 826915Safaricom Offers by - 2547******109 NAOMI MUREITHI | D16: Completed | F16: 10 | G16: 2080 | L16: =IF(ISNUMBER(SEARCH("Bundle",C16)),"Bundles",IF(ISNUMBER(SEARCH("Airtime",C16)),"Bundles",IF(ISNUMBER(SEARCH("Merchant",C16)),"Merchant Payment",IF(ISNUMBER(SEARCH("Offnet C2B",C16)),"Merchant Payment",IF(ISNUMBER(SEARCH("Offnet B2C",C16)),"Merchant Payment",IF(ISNUMBER(SEARCH("Customer Payment to Small",C16)),"Merchant Payment",IF(ISNUMBER(SEARCH("Payment to Small Business",C16)),"Merchant Payment",IF(ISNUMBER(SEARCH("Sent to",C16)),"Sent to Person",IF(ISNUMBER(SEARCH("Customer Transfer to",C16)),"Sent to Person",IF(ISNUMBER(SEARCH("Business Payment",C16)),"Money In",IF(ISNUMBER(SEARCH("Funds Received",C16)),"Money In",IF(ISNUMBER(SEARCH("Receive International",C16)),"Money In",IF(ISNUMBER(SEARCH("Send Money Reversal",C16)),"Money In",IF(ISNUMBER(SEARCH("Pay Utility Reversal",C16)),"Money In",IF(ISNUMBER(SEARCH("Customer Transfer",C16)),"Money In",IF(ISNUMBER(SEARCH("Ziidi",C16)),"Investment",IF(ISNUMBER(SEARCH("Nabo",C16)),"Investment",IF(ISNUMBER(SEARCH("Paybill Online",C16)),"Pay Bill",IF(ISNUMBER(SEARCH("Pay Bill",C16)),"Pay Bill",IF(ISNUMBER(SEARCH("Spotify",C16)),"Pay Bill",IF(ISNUMBER(SEARCH("M-Shwari",C16)),"Mshwari",IF(ISNUMBER(SEARCH("Mshwari",C16)),"Mshwari",IF(ISNUMBER(SEARCH("Withdrawal charge",C16)),"Fees",IF(ISNUMBER(SEARCH("Customer Withdrawal",C16)),"Fees",IF(ISNUMBER(SEARCH("charge",C16)),"Fees","Other"))))))))))))))))))))))))) -> Bundles | R16: =TEXT(B2,"MMM YYYY") -> Jan 2026
A17: UADA93MUBH | B17: 2026-01-13 14:27:42 | C17: Customer Bundle Purchase to 4093441SAFARICOM DATA BUNDLES by - 2547******109 NAOMI MUREITHI | D17: Completed | F17: 10 | G17: 2070 | L17: =IF(ISNUMBER(SEARCH("Bundle",C17)),"Bundles",IF(ISNUMBER(SEARCH("Airtime",C17)),"Bundles",IF(ISNUMBER(SEARCH("Merchant",C17)),"Merchant Payment",IF(ISNUMBER(SEARCH("Offnet C2B",C17)),"Merchant Payment",IF(ISNUMBER(SEARCH("Offnet B2C",C17)),"Merchant Payment",IF(ISNUMBER(SEARCH("Customer Payment to Small",C17)),"Merchant Payment",IF(ISNUMBER(SEARCH("Payment to Small Business",C17)),"Merchant Payment",IF(ISNUMBER(SEARCH("Sent to",C17)),"Sent to Person",IF(ISNUMBER(SEARCH("Customer Transfer to",C17)),"Sent to Person",IF(ISNUMBER(SEARCH("Business Payment",C17)),"Money In",IF(ISNUMBER(SEARCH("Funds Received",C17)),"Money In",IF(ISNUMBER(SEARCH("Receive International",C17)),"Money In",IF(ISNUMBER(SEARCH("Send Money Reversal",C17)),"Money In",IF(ISNUMBER(SEARCH("Pay Utility Reversal",C17)),"Money In",IF(ISNUMBER(SEARCH("Customer Transfer",C17)),"Money In",IF(ISNUMBER(SEARCH("Ziidi",C17)),"Investment",IF(ISNUMBER(SEARCH("Nabo",C17)),"Investment",IF(ISNUMBER(SEARCH("Paybill Online",C17)),"Pay Bill",IF(ISNUMBER(SEARCH("Pay Bill",C17)),"Pay Bill",IF(ISNUMBER(SEARCH("Spotify",C17)),"Pay Bill",IF(ISNUMBER(SEARCH("M-Shwari",C17)),"Mshwari",IF(ISNUMBER(SEARCH("Mshwari",C17)),"Mshwari",IF(ISNUMBER(SEARCH("Withdrawal charge",C17)),"Fees",IF(ISNUMBER(SEARCH("Customer Withdrawal",C17)),"Fees",IF(ISNUMBER(SEARCH("charge",C17)),"Fees","Other"))))))))))))))))))))))))) -> Bundles | R17: =TEXT(B2,"MMM YYYY") -> Jan 2026
A18: UADA93NAPT | B18: 2026-01-13 18:03:09 | C18: Customer Bundle Purchase to 4093441SAFARICOM DATA BUNDLES by - 2547******109 NAOMI MUREITHI | D18: Completed | F18: 10 | G18: 2060 | L18: =IF(ISNUMBER(SEARCH("Bundle",C18)),"Bundles",IF(ISNUMBER(SEARCH("Airtime",C18)),"Bundles",IF(ISNUMBER(SEARCH("Merchant",C18)),"Merchant Payment",IF(ISNUMBER(SEARCH("Offnet C2B",C18)),"Merchant Payment",IF(ISNUMBER(SEARCH("Offnet B2C",C18)),"Merchant Payment",IF(ISNUMBER(SEARCH("Customer Payment to Small",C18)),"Merchant Payment",IF(ISNUMBER(SEARCH("Payment to Small Business",C18)),"Merchant Payment",IF(ISNUMBER(SEARCH("Sent to",C18)),"Sent to Person",IF(ISNUMBER(SEARCH("Customer Transfer to",C18)),"Sent to Person",IF(ISNUMBER(SEARCH("Business Payment",C18)),"Money In",IF(ISNUMBER(SEARCH("Funds Received",C18)),"Money In",IF(ISNUMBER(SEARCH("Receive International",C18)),"Money In",IF(ISNUMBER(SEARCH("Send Money Reversal",C18)),"Money In",IF(ISNUMBER(SEARCH("Pay Utility Reversal",C18)),"Money In",IF(ISNUMBER(SEARCH("Customer Transfer",C18)),"Money In",IF(ISNUMBER(SEARCH("Ziidi",C18)),"Investment",IF(ISNUMBER(SEARCH("Nabo",C18)),"Investment",IF(ISNUMBER(SEARCH("Paybill Online",C18)),"Pay Bill",IF(ISNUMBER(SEARCH("Pay Bill",C18)),"Pay Bill",IF(ISNUMBER(SEARCH("Spotify",C18)),"Pay Bill",IF(ISNUMBER(SEARCH("M-Shwari",C18)),"Mshwari",IF(ISNUMBER(SEARCH("Mshwari",C18)),"Mshwari",IF(ISNUMBER(SEARCH("Withdrawal charge",C18)),"Fees",IF(ISNUMBER(SEARCH("Customer Withdrawal",C18)),"Fees",IF(ISNUMBER(SEARCH("charge",C18)),"Fees","Other"))))))))))))))))))))))))) -> Bundles | R18: =TEXT(B2,"MMM YYYY") -> Jan 2026
A19: UADA93NSWI | B19: 2026-01-13 19:47:14 | C19: Customer Bundle Purchase to 4093441SAFARICOM DATA BUNDLES by - 2547******109 NAOMI MUREITHI | D19: Completed | F19: 10 | G19: 2050 | L19: =IF(ISNUMBER(SEARCH("Bundle",C19)),"Bundles",IF(ISNUMBER(SEARCH("Airtime",C19)),"Bundles",IF(ISNUMBER(SEARCH("Merchant",C19)),"Merchant Payment",IF(ISNUMBER(SEARCH("Offnet C2B",C19)),"Merchant Payment",IF(ISNUMBER(SEARCH("Offnet B2C",C19)),"Merchant Payment",IF(ISNUMBER(SEARCH("Customer Payment to Small",C19)),"Merchant Payment",IF(ISNUMBER(SEARCH("Payment to Small Business",C19)),"Merchant Payment",IF(ISNUMBER(SEARCH("Sent to",C19)),"Sent to Person",IF(ISNUMBER(SEARCH("Customer Transfer to",C19)),"Sent to Person",IF(ISNUMBER(SEARCH("Business Payment",C19)),"Money In",IF(ISNUMBER(SEARCH("Funds Received",C19)),"Money In",IF(ISNUMBER(SEARCH("Receive International",C19)),"Money In",IF(ISNUMBER(SEARCH("Send Money Reversal",C19)),"Money In",IF(ISNUMBER(SEARCH("Pay Utility Reversal",C19)),"Money In",IF(ISNUMBER(SEARCH("Customer Transfer",C19)),"Money In",IF(ISNUMBER(SEARCH("Ziidi",C19)),"Investment",IF(ISNUMBER(SEARCH("Nabo",C19)),"Investment",IF(ISNUMBER(SEARCH("Paybill Online",C19)),"Pay Bill",IF(ISNUMBER(SEARCH("Pay Bill",C19)),"Pay Bill",IF(ISNUMBER(SEARCH("Spotify",C19)),"Pay Bill",IF(ISNUMBER(SEARCH("M-Shwari",C19)),"Mshwari",IF(ISNUMBER(SEARCH("Mshwari",C19)),"Mshwari",IF(ISNUMBER(SEARCH("Withdrawal charge",C19)),"Fees",IF(ISNUMBER(SEARCH("Customer Withdrawal",C19)),"Fees",IF(ISNUMBER(SEARCH("charge",C19)),"Fees","Other"))))))))))))))))))))))))) -> Bundles | R19: =TEXT(B2,"MMM YYYY") -> Jan 2026
A20: UAEA93OZUW | B20: 2026-01-14 09:08:44 | C20: Customer Bundle Purchase to 4093441SAFARICOM DATA BUNDLES by - 2547******109 NAOMI MUREITHI | D20: Completed | F20: 10 | G20: 2040 | L20: =IF(ISNUMBER(SEARCH("Bundle",C20)),"Bundles",IF(ISNUMBER(SEARCH("Airtime",C20)),"Bundles",IF(ISNUMBER(SEARCH("Merchant",C20)),"Merchant Payment",IF(ISNUMBER(SEARCH("Offnet C2B",C20)),"Merchant Payment",IF(ISNUMBER(SEARCH("Offnet B2C",C20)),"Merchant Payment",IF(ISNUMBER(SEARCH("Customer Payment to Small",C20)),"Merchant Payment",IF(ISNUMBER(SEARCH("Payment to Small Business",C20)),"Merchant Payment",IF(ISNUMBER(SEARCH("Sent to",C20)),"Sent to Person",IF(ISNUMBER(SEARCH("Customer Transfer to",C20)),"Sent to Person",IF(ISNUMBER(SEARCH("Business Payment",C20)),"Money In",IF(ISNUMBER(SEARCH("Funds Received",C20)),"Money In",IF(ISNUMBER(SEARCH("Receive International",C20)),"Money In",IF(ISNUMBER(SEARCH("Send Money Reversal",C20)),"Money In",IF(ISNUMBER(SEARCH("Pay Utility Reversal",C20)),"Money In",IF(ISNUMBER(SEARCH("Customer Transfer",C20)),"Money In",IF(ISNUMBER(SEARCH("Ziidi",C20)),"Investment",IF(ISNUMBER(SEARCH("Nabo",C20)),"Investment",IF(ISNUMBER(SEARCH("Paybill Online",C20)),"Pay Bill",IF(ISNUMBER(SEARCH("Pay Bill",C20)),"Pay Bill",IF(ISNUMBER(SEARCH("Spotify",C20)),"Pay Bill",IF(ISNUMBER(SEARCH("M-Shwari",C20)),"Mshwari",IF(ISNUMBER(SEARCH("Mshwari",C20)),"Mshwari",IF(ISNUMBER(SEARCH("Withdrawal charge",C20)),"Fees",IF(ISNUMBER(SEARCH("Customer Withdrawal",C20)),"Fees",IF(ISNUMBER(SEARCH("charge",C20)),"Fees","Other"))))))))))))))))))))))))) -> Bundles | R20: =TEXT(B2,"MMM YYYY") -> Jan 2026
A21: UAEA93PEPB | B21: 2026-01-14 10:27:47 | C21: Customer Bundle Purchase to 4093441SAFARICOM DATA BUNDLES by - 2547******109 NAOMI MUREITHI | D21: Completed | F21: 30 | G21: 2010 | L21: =IF(ISNUMBER(SEARCH("Bundle",C21)),"Bundles",IF(ISNUMBER(SEARCH("Airtime",C21)),"Bundles",IF(ISNUMBER(SEARCH("Merchant",C21)),"Merchant Payment",IF(ISNUMBER(SEARCH("Offnet C2B",C21)),"Merchant Payment",IF(ISNUMBER(SEARCH("Offnet B2C",C21)),"Merchant Payment",IF(ISNUMBER(SEARCH("Customer Payment to Small",C21)),"Merchant Payment",IF(ISNUMBER(SEARCH("Payment to Small Business",C21)),"Merchant Payment",IF(ISNUMBER(SEARCH("Sent to",C21)),"Sent to Person",IF(ISNUMBER(SEARCH("Customer Transfer to",C21)),"Sent to Person",IF(ISNUMBER(SEARCH("Business Payment",C21)),"Money In",IF(ISNUMBER(SEARCH("Funds Received",C21)),"Money In",IF(ISNUMBER(SEARCH("Receive International",C21)),"Money In",IF(ISNUMBER(SEARCH("Send Money Reversal",C21)),"Money In",IF(ISNUMBER(SEARCH("Pay Utility Reversal",C21)),"Money In",IF(ISNUMBER(SEARCH("Customer Transfer",C21)),"Money In",IF(ISNUMBER(SEARCH("Ziidi",C21)),"Investment",IF(ISNUMBER(SEARCH("Nabo",C21)),"Investment",IF(ISNUMBER(SEARCH("Paybill Online",C21)),"Pay Bill",IF(ISNUMBER(SEARCH("Pay Bill",C21)),"Pay Bill",IF(ISNUMBER(SEARCH("Spotify",C21)),"Pay Bill",IF(ISNUMBER(SEARCH("M-Shwari",C21)),"Mshwari",IF(ISNUMBER(SEARCH("Mshwari",C21)),"Mshwari",IF(ISNUMBER(SEARCH("Withdrawal charge",C21)),"Fees",IF(ISNUMBER(SEARCH("Customer Withdrawal",C21)),"Fees",IF(ISNUMBER(SEARCH("charge",C21)),"Fees","Other"))))))))))))))))))))))))) -> Bundles | R21: =TEXT(B2,"MMM YYYY") -> Jan 2026
A22: UAEA93R22B | B22: 2026-01-14 19:14:37 | C22: Customer Bundle Purchase to 4093441SAFARICOM DATA BUNDLES by - 2547******109 NAOMI MUREITHI | D22: Completed | F22: 30 | G22: 1980 | L22: =IF(ISNUMBER(SEARCH("Bundle",C22)),"Bundles",IF(ISNUMBER(SEARCH("Airtime",C22)),"Bundles",IF(ISNUMBER(SEARCH("Merchant",C22)),"Merchant Payment",IF(ISNUMBER(SEARCH("Offnet C2B",C22)),"Merchant Payment",IF(ISNUMBER(SEARCH("Offnet B2C",C22)),"Merchant Payment",IF(ISNUMBER(SEARCH("Customer Payment to Small",C22)),"Merchant Payment",IF(ISNUMBER(SEARCH("Payment to Small Business",C22)),"Merchant Payment",IF(ISNUMBER(SEARCH("Sent to",C22)),"Sent to Person",IF(ISNUMBER(SEARCH("Customer Transfer to",C22)),"Sent to Person",IF(ISNUMBER(SEARCH("Business Payment",C22)),"Money In",IF(ISNUMBER(SEARCH("Funds Received",C22)),"Money In",IF(ISNUMBER(SEARCH("Receive International",C22)),"Money In",IF(ISNUMBER(SEARCH("Send Money Reversal",C22)),"Money In",IF(ISNUMBER(SEARCH("Pay Utility Reversal",C22)),"Money In",IF(ISNUMBER(SEARCH("Customer Transfer",C22)),"Money In",IF(ISNUMBER(SEARCH("Ziidi",C22)),"Investment",IF(ISNUMBER(SEARCH("Nabo",C22)),"Investment",IF(ISNUMBER(SEARCH("Paybill Online",C22)),"Pay Bill",IF(ISNUMBER(SEARCH("Pay Bill",C22)),"Pay Bill",IF(ISNUMBER(SEARCH("Spotify",C22)),"Pay Bill",IF(ISNUMBER(SEARCH("M-Shwari",C22)),"Mshwari",IF(ISNUMBER(SEARCH("Mshwari",C22)),"Mshwari",IF(ISNUMBER(SEARCH("Withdrawal charge",C22)),"Fees",IF(ISNUMBER(SEARCH("Customer Withdrawal",C22)),"Fees",IF(ISNUMBER(SEARCH("charge",C22)),"Fees","Other"))))))))))))))))))))))))) -> Bundles | R22: =TEXT(B2,"MMM YYYY") -> Jan 2026
A23: UAFA93SXMQ | B23: 2026-01-15 12:07:00 | C23: Customer Bundle Purchase to 4093441SAFARICOM DATA BUNDLES by - 2547******109 NAOMI MUREITHI | D23: Completed | F23: 30 | G23: 1950 | L23: =IF(ISNUMBER(SEARCH("Bundle",C23)),"Bundles",IF(ISNUMBER(SEARCH("Airtime",C23)),"Bundles",IF(ISNUMBER(SEARCH("Merchant",C23)),"Merchant Payment",IF(ISNUMBER(SEARCH("Offnet C2B",C23)),"Merchant Payment",IF(ISNUMBER(SEARCH("Offnet B2C",C23)),"Merchant Payment",IF(ISNUMBER(SEARCH("Customer Payment to Small",C23)),"Merchant Payment",IF(ISNUMBER(SEARCH("Payment to Small Business",C23)),"Merchant Payment",IF(ISNUMBER(SEARCH("Sent to",C23)),"Sent to Person",IF(ISNUMBER(SEARCH("Customer Transfer to",C23)),"Sent to Person",IF(ISNUMBER(SEARCH("Business Payment",C23)),"Money In",IF(ISNUMBER(SEARCH("Funds Received",C23)),"Money In",IF(ISNUMBER(SEARCH("Receive International",C23)),"Money In",IF(ISNUMBER(SEARCH("Send Money Reversal",C23)),"Money In",IF(ISNUMBER(SEARCH("Pay Utility Reversal",C23)),"Money In",IF(ISNUMBER(SEARCH("Customer Transfer",C23)),"Money In",IF(ISNUMBER(SEARCH("Ziidi",C23)),"Investment",IF(ISNUMBER(SEARCH("Nabo",C23)),"Investment",IF(ISNUMBER(SEARCH("Paybill Online",C23)),"Pay Bill",IF(ISNUMBER(SEARCH("Pay Bill",C23)),"Pay Bill",IF(ISNUMBER(SEARCH("Spotify",C23)),"Pay Bill",IF(ISNUMBER(SEARCH("M-Shwari",C23)),"Mshwari",IF(ISNUMBER(SEARCH("Mshwari",C23)),"Mshwari",IF(ISNUMBER(SEARCH("Withdrawal charge",C23)),"Fees",IF(ISNUMBER(SEARCH("Customer Withdrawal",C23)),"Fees",IF(ISNUMBER(SEARCH("charge",C23)),"Fees","Other"))))))))))))))))))))))))) -> Bundles | R23: =TEXT(B2,"MMM YYYY") -> Jan 2026
A24: UAFA93TILA | B24: 2026-01-15 16:08:20 | C24: Customer Bundle Purchase to 4093441SAFARICOM DATA BUNDLES by - 2547******109 NAOMI MUREITHI | D24: Completed | F24: 30 | G24: 1920 | L24: =IF(ISNUMBER(SEARCH("Bundle",C24)),"Bundles",IF(ISNUMBER(SEARCH("Airtime",C24)),"Bundles",IF(ISNUMBER(SEARCH("Merchant",C24)),"Merchant Payment",IF(ISNUMBER(SEARCH("Offnet C2B",C24)),"Merchant Payment",IF(ISNUMBER(SEARCH("Offnet B2C",C24)),"Merchant Payment",IF(ISNUMBER(SEARCH("Customer Payment to Small",C24)),"Merchant Payment",IF(ISNUMBER(SEARCH("Payment to Small Business",C24)),"Merchant Payment",IF(ISNUMBER(SEARCH("Sent to",C24)),"Sent to Person",IF(ISNUMBER(SEARCH("Customer Transfer to",C24)),"Sent to Person",IF(ISNUMBER(SEARCH("Business Payment",C24)),"Money In",IF(ISNUMBER(SEARCH("Funds Received",C24)),"Money In",IF(ISNUMBER(SEARCH("Receive International",C24)),"Money In",IF(ISNUMBER(SEARCH("Send Money Reversal",C24)),"Money In",IF(ISNUMBER(SEARCH("Pay Utility Reversal",C24)),"Money In",IF(ISNUMBER(SEARCH("Customer Transfer",C24)),"Money In",IF(ISNUMBER(SEARCH("Ziidi",C24)),"Investment",IF(ISNUMBER(SEARCH("Nabo",C24)),"Investment",IF(ISNUMBER(SEARCH("Paybill Online",C24)),"Pay Bill",IF(ISNUMBER(SEARCH("Pay Bill",C24)),"Pay Bill",IF(ISNUMBER(SEARCH("Spotify",C24)),"Pay Bill",IF(ISNUMBER(SEARCH("M-Shwari",C24)),"Mshwari",IF(ISNUMBER(SEARCH("Mshwari",C24)),"Mshwari",IF(ISNUMBER(SEARCH("Withdrawal charge",C24)),"Fees",IF(ISNUMBER(SEARCH("Customer Withdrawal",C24)),"Fees",IF(ISNUMBER(SEARCH("charge",C24)),"Fees","Other"))))))))))))))))))))))))) -> Bundles | R24: =TEXT(B2,"MMM YYYY") -> Jan 2026
A25: UAFA93ULQZ | B25: 2026-01-15 19:29:44 | C25: Customer Bundle Purchase to 4093441SAFARICOM DATA BUNDLES by - 2547******109 NAOMI MUREITHI | D25: Completed | F25: 10 | G25: 1910 | L25: =IF(ISNUMBER(SEARCH("Bundle",C25)),"Bundles",IF(ISNUMBER(SEARCH("Airtime",C25)),"Bundles",IF(ISNUMBER(SEARCH("Merchant",C25)),"Merchant Payment",IF(ISNUMBER(SEARCH("Offnet C2B",C25)),"Merchant Payment",IF(ISNUMBER(SEARCH("Offnet B2C",C25)),"Merchant Payment",IF(ISNUMBER(SEARCH("Customer Payment to Small",C25)),"Merchant Payment",IF(ISNUMBER(SEARCH("Payment to Small Business",C25)),"Merchant Payment",IF(ISNUMBER(SEARCH("Sent to",C25)),"Sent to Person",IF(ISNUMBER(SEARCH("Customer Transfer to",C25)),"Sent to Person",IF(ISNUMBER(SEARCH("Business Payment",C25)),"Money In",IF(ISNUMBER(SEARCH("Funds Received",C25)),"Money In",IF(ISNUMBER(SEARCH("Receive International",C25)),"Money In",IF(ISNUMBER(SEARCH("Send Money Reversal",C25)),"Money In",IF(ISNUMBER(SEARCH("Pay Utility Reversal",C25)),"Money In",IF(ISNUMBER(SEARCH("Customer Transfer",C25)),"Money In",IF(ISNUMBER(SEARCH("Ziidi",C25)),"Investment",IF(ISNUMBER(SEARCH("Nabo",C25)),"Investment",IF(ISNUMBER(SEARCH("Paybill Online",C25)),"Pay Bill",IF(ISNUMBER(SEARCH("Pay Bill",C25)),"Pay Bill",IF(ISNUMBER(SEARCH("Spotify",C25)),"Pay Bill",IF(ISNUMBER(SEARCH("M-Shwari",C25)),"Mshwari",IF(ISNUMBER(SEARCH("Mshwari",C25)),"Mshwari",IF(ISNUMBER(SEARCH("Withdrawal charge",C25)),"Fees",IF(ISNUMBER(SEARCH("Customer Withdrawal",C25)),"Fees",IF(ISNUMBER(SEARCH("charge",C25)),"Fees","Other"))))))))))))))))))))))))) -> Bundles | R25: =TEXT(B2,"MMM YYYY") -> Jan 2026
A26: UAFA93V31J | B26: 2026-01-15 21:33:55 | C26: Customer Bundle Purchase to 4093441SAFARICOM DATA BUNDLES by - 2547******109 NAOMI MUREITHI | D26: Completed | F26: 10 | G26: 1900 | L26: =IF(ISNUMBER(SEARCH("Bundle",C26)),"Bundles",IF(ISNUMBER(SEARCH("Airtime",C26)),"Bundles",IF(ISNUMBER(SEARCH("Merchant",C26)),"Merchant Payment",IF(ISNUMBER(SEARCH("Offnet C2B",C26)),"Merchant Payment",IF(ISNUMBER(SEARCH("Offnet B2C",C26)),"Merchant Payment",IF(ISNUMBER(SEARCH("Customer Payment to Small",C26)),"Merchant Payment",IF(ISNUMBER(SEARCH("Payment to Small Business",C26)),"Merchant Payment",IF(ISNUMBER(SEARCH("Sent to",C26)),"Sent to Person",IF(ISNUMBER(SEARCH("Customer Transfer to",C26)),"Sent to Person",IF(ISNUMBER(SEARCH("Business Payment",C26)),"Money In",IF(ISNUMBER(SEARCH("Funds Received",C26)),"Money In",IF(ISNUMBER(SEARCH("Receive International",C26)),"Money In",IF(ISNUMBER(SEARCH("Send Money Reversal",C26)),"Money In",IF(ISNUMBER(SEARCH("Pay Utility Reversal",C26)),"Money In",IF(ISNUMBER(SEARCH("Customer Transfer",C26)),"Money In",IF(ISNUMBER(SEARCH("Ziidi",C26)),"Investment",IF(ISNUMBER(SEARCH("Nabo",C26)),"Investment",IF(ISNUMBER(SEARCH("Paybill Online",C26)),"Pay Bill",IF(ISNUMBER(SEARCH("Pay Bill",C26)),"Pay Bill",IF(ISNUMBER(SEARCH("Spotify",C26)),"Pay Bill",IF(ISNUMBER(SEARCH("M-Shwari",C26)),"Mshwari",IF(ISNUMBER(SEARCH("Mshwari",C26)),"Mshwari",IF(ISNUMBER(SEARCH("Withdrawal charge",C26)),"Fees",IF(ISNUMBER(SEARCH("Customer Withdrawal",C26)),"Fees",IF(ISNUMBER(SEARCH("charge",C26)),"Fees","Other"))))))))))))))))))))))))) -> Bundles | R26: =TEXT(B2,"MMM YYYY") -> Jan 2026
A27: UAGA93VFFB | B27: 2026-01-16 03:03:48 | C27: Customer Bundle Purchase to 4093441SAFARICOM DATA BUNDLES by - 2547******109 NAOMI MUREITHI | D27: Completed | F27: 30 | G27: 1870 | L27: =IF(ISNUMBER(SEARCH("Bundle",C27)),"Bundles",IF(ISNUMBER(SEARCH("Airtime",C27)),"Bundles",IF(ISNUMBER(SEARCH("Merchant",C27)),"Merchant Payment",IF(ISNUMBER(SEARCH("Offnet C2B",C27)),"Merchant Payment",IF(ISNUMBER(SEARCH("Offnet B2C",C27)),"Merchant Payment",IF(ISNUMBER(SEARCH("Customer Payment to Small",C27)),"Merchant Payment",IF(ISNUMBER(SEARCH("Payment to Small Business",C27)),"Merchant Payment",IF(ISNUMBER(SEARCH("Sent to",C27)),"Sent to Person",IF(ISNUMBER(SEARCH("Customer Transfer to",C27)),"Sent to Person",IF(ISNUMBER(SEARCH("Business Payment",C27)),"Money In",IF(ISNUMBER(SEARCH("Funds Received",C27)),"Money In",IF(ISNUMBER(SEARCH("Receive International",C27)),"Money In",IF(ISNUMBER(SEARCH("Send Money Reversal",C27)),"Money In",IF(ISNUMBER(SEARCH("Pay Utility Reversal",C27)),"Money In",IF(ISNUMBER(SEARCH("Customer Transfer",C27)),"Money In",IF(ISNUMBER(SEARCH("Ziidi",C27)),"Investment",IF(ISNUMBER(SEARCH("Nabo",C27)),"Investment",IF(ISNUMBER(SEARCH("Paybill Online",C27)),"Pay Bill",IF(ISNUMBER(SEARCH("Pay Bill",C27)),"Pay Bill",IF(ISNUMBER(SEARCH("Spotify",C27)),"Pay Bill",IF(ISNUMBER(SEARCH("M-Shwari",C27)),"Mshwari",IF(ISNUMBER(SEARCH("Mshwari",C27)),"Mshwari",IF(ISNUMBER(SEARCH("Withdrawal charge",C27)),"Fees",IF(ISNUMBER(SEARCH("Customer Withdrawal",C27)),"Fees",IF(ISNUMBER(SEARCH("charge",C27)),"Fees","Other"))))))))))))))))))))))))) -> Bundles | R27: =TEXT(B2,"MMM YYYY") -> Jan 2026
A28: UAGA93X06J | B28: 2026-01-16 15:14:25 | C28: Customer Bundle Purchase to 4093441SAFARICOM DATA BUNDLES by - 2547******109 NAOMI MUREITHI | D28: Completed | F28: 20 | G28: 1850 | L28: =IF(ISNUMBER(SEARCH("Bundle",C28)),"Bundles",IF(ISNUMBER(SEARCH("Airtime",C28)),"Bundles",IF(ISNUMBER(SEARCH("Merchant",C28)),"Merchant Payment",IF(ISNUMBER(SEARCH("Offnet C2B",C28)),"Merchant Payment",IF(ISNUMBER(SEARCH("Offnet B2C",C28)),"Merchant Payment",IF(ISNUMBER(SEARCH("Customer Payment to Small",C28)),"Merchant Payment",IF(ISNUMBER(SEARCH("Payment to Small Business",C28)),"Merchant Payment",IF(ISNUMBER(SEARCH("Sent to",C28)),"Sent to Person",IF(ISNUMBER(SEARCH("Customer Transfer to",C28)),"Sent to Person",IF(ISNUMBER(SEARCH("Business Payment",C28)),"Money In",IF(ISNUMBER(SEARCH("Funds Received",C28)),"Money In",IF(ISNUMBER(SEARCH("Receive International",C28)),"Money In",IF(ISNUMBER(SEARCH("Send Money Reversal",C28)),"Money In",IF(ISNUMBER(SEARCH("Pay Utility Reversal",C28)),"Money In",IF(ISNUMBER(SEARCH("Customer Transfer",C28)),"Money In",IF(ISNUMBER(SEARCH("Ziidi",C28)),"Investment",IF(ISNUMBER(SEARCH("Nabo",C28)),"Investment",IF(ISNUMBER(SEARCH("Paybill Online",C28)),"Pay Bill",IF(ISNUMBER(SEARCH("Pay Bill",C28)),"Pay Bill",IF(ISNUMBER(SEARCH("Spotify",C28)),"Pay Bill",IF(ISNUMBER(SEARCH("M-Shwari",C28)),"Mshwari",IF(ISNUMBER(SEARCH("Mshwari",C28)),"Mshwari",IF(ISNUMBER(SEARCH("Withdrawal charge",C28)),"Fees",IF(ISNUMBER(SEARCH("Customer Withdrawal",C28)),"Fees",IF(ISNUMBER(SEARCH("charge",C28)),"Fees","Other"))))))))))))))))))))))))) -> Bundles
A29: UAGA93XF01 | B29: 2026-01-16 18:19:45 | C29: Customer Bundle Purchase to 4093441SAFARICOM DATA BUNDLES by - 2547******109 NAOMI MUREITHI | D29: Completed | F29: 10 | G29: 1840 | L29: =IF(ISNUMBER(SEARCH("Bundle",C29)),"Bundles",IF(ISNUMBER(SEARCH("Airtime",C29)),"Bundles",IF(ISNUMBER(SEARCH("Merchant",C29)),"Merchant Payment",IF(ISNUMBER(SEARCH("Offnet C2B",C29)),"Merchant Payment",IF(ISNUMBER(SEARCH("Offnet B2C",C29)),"Merchant Payment",IF(ISNUMBER(SEARCH("Customer Payment to Small",C29)),"Merchant Payment",IF(ISNUMBER(SEARCH("Payment to Small Business",C29)),"Merchant Payment",IF(ISNUMBER(SEARCH("Sent to",C29)),"Sent to Person",IF(ISNUMBER(SEARCH("Customer Transfer to",C29)),"Sent to Person",IF(ISNUMBER(SEARCH("Business Payment",C29)),"Money In",IF(ISNUMBER(SEARCH("Funds Received",C29)),"Money In",IF(ISNUMBER(SEARCH("Receive International",C29)),"Money In",IF(ISNUMBER(SEARCH("Send Money Reversal",C29)),"Money In",IF(ISNUMBER(SEARCH("Pay Utility Reversal",C29)),"Money In",IF(ISNUMBER(SEARCH("Customer Transfer",C29)),"Money In",IF(ISNUMBER(SEARCH("Ziidi",C29)),"Investment",IF(ISNUMBER(SEARCH("Nabo",C29)),"Investment",IF(ISNUMBER(SEARCH("Paybill Online",C29)),"Pay Bill",IF(ISNUMBER(SEARCH("Pay Bill",C29)),"Pay Bill",IF(ISNUMBER(SEARCH("Spotify",C29)),"Pay Bill",IF(ISNUMBER(SEARCH("M-Shwari",C29)),"Mshwari",IF(ISNUMBER(SEARCH("Mshwari",C29)),"Mshwari",IF(ISNUMBER(SEARCH("Withdrawal charge",C29)),"Fees",IF(ISNUMBER(SEARCH("Customer Withdrawal",C29)),"Fees",IF(ISNUMBER(SEARCH("charge",C29)),"Fees","Other"))))))))))))))))))))))))) -> Bundles
A30: UAGA93XVXO | B30: 2026-01-16 19:34:53 | C30: Customer Bundle Purchase to | D30: Completed | F30: 10 | G30: 1830 | L30: =IF(ISNUMBER(SEARCH("Bundle",C30)),"Bundles",IF(ISNUMBER(SEARCH("Airtime",C30)),"Bundles",IF(ISNUMBER(SEARCH("Merchant",C30)),"Merchant Payment",IF(ISNUMBER(SEARCH("Offnet C2B",C30)),"Merchant Payment",IF(ISNUMBER(SEARCH("Offnet B2C",C30)),"Merchant Payment",IF(ISNUMBER(SEARCH("Customer Payment to Small",C30)),"Merchant Payment",IF(ISNUMBER(SEARCH("Payment to Small Business",C30)),"Merchant Payment",IF(ISNUMBER(SEARCH("Sent to",C30)),"Sent to Person",IF(ISNUMBER(SEARCH("Customer Transfer to",C30)),"Sent to Person",IF(ISNUMBER(SEARCH("Business Payment",C30)),"Money In",IF(ISNUMBER(SEARCH("Funds Received",C30)),"Money In",IF(ISNUMBER(SEARCH("Receive International",C30)),"Money In",IF(ISNUMBER(SEARCH("Send Money Reversal",C30)),"Money In",IF(ISNUMBER(SEARCH("Pay Utility Reversal",C30)),"Money In",IF(ISNUMBER(SEARCH("Customer Transfer",C30)),"Money In",IF(ISNUMBER(SEARCH("Ziidi",C30)),"Investment",IF(ISNUMBER(SEARCH("Nabo",C30)),"Investment",IF(ISNUMBER(SEARCH("Paybill Online",C30)),"Pay Bill",IF(ISNUMBER(SEARCH("Pay Bill",C30)),"Pay Bill",IF(ISNUMBER(SEARCH("Spotify",C30)),"Pay Bill",IF(ISNUMBER(SEARCH("M-Shwari",C30)),"Mshwari",IF(ISNUMBER(SEARCH("Mshwari",C30)),"Mshwari",IF(ISNUMBER(SEARCH("Withdrawal charge",C30)),"Fees",IF(ISNUMBER(SEARCH("Customer Withdrawal",C30)),"Fees",IF(ISNUMBER(SEARCH("charge",C30)),"Fees","Other"))))))))))))))))))))))))) -> Bundles
A31: UAGA93YOAJ | B31: 2026-01-16 22:10:56 | C31: Customer Bundle Purchase to | D31: Completed | F31: 10 | G31: 1820 | L31: =IF(ISNUMBER(SEARCH("Bundle",C31)),"Bundles",IF(ISNUMBER(SEARCH("Airtime",C31)),"Bundles",IF(ISNUMBER(SEARCH("Merchant",C31)),"Merchant Payment",IF(ISNUMBER(SEARCH("Offnet C2B",C31)),"Merchant Payment",IF(ISNUMBER(SEARCH("Offnet B2C",C31)),"Merchant Payment",IF(ISNUMBER(SEARCH("Customer Payment to Small",C31)),"Merchant Payment",IF(ISNUMBER(SEARCH("Payment to Small Business",C31)),"Merchant Payment",IF(ISNUMBER(SEARCH("Sent to",C31)),"Sent to Person",IF(ISNUMBER(SEARCH("Customer Transfer to",C31)),"Sent to Person",IF(ISNUMBER(SEARCH("Business Payment",C31)),"Money In",IF(ISNUMBER(SEARCH("Funds Received",C31)),"Money In",IF(ISNUMBER(SEARCH("Receive International",C31)),"Money In",IF(ISNUMBER(SEARCH("Send Money Reversal",C31)),"Money In",IF(ISNUMBER(SEARCH("Pay Utility Reversal",C31)),"Money In",IF(ISNUMBER(SEARCH("Customer Transfer",C31)),"Money In",IF(ISNUMBER(SEARCH("Ziidi",C31)),"Investment",IF(ISNUMBER(SEARCH("Nabo",C31)),"Investment",IF(ISNUMBER(SEARCH("Paybill Online",C31)),"Pay Bill",IF(ISNUMBER(SEARCH("Pay Bill",C31)),"Pay Bill",IF(ISNUMBER(SEARCH("Spotify",C31)),"Pay Bill",IF(ISNUMBER(SEARCH("M-Shwari",C31)),"Mshwari",IF(ISNUMBER(SEARCH("Mshwari",C31)),"Mshwari",IF(ISNUMBER(SEARCH("Withdrawal charge",C31)),"Fees",IF(ISNUMBER(SEARCH("Customer Withdrawal",C31)),"Fees",IF(ISNUMBER(SEARCH("charge",C31)),"Fees","Other"))))))))))))))))))))))))) -> Bundles | R31: =TEXT(B2,"MMM YYYY") -> Jan 2026
A32: UAHA93YTJ4 | B32: 2026-01-17 04:28:25 | C32: Customer Bundle Purchase to | D32: Completed | F32: 30 | G32: 1790 | L32: =IF(ISNUMBER(SEARCH("Bundle",C32)),"Bundles",IF(ISNUMBER(SEARCH("Airtime",C32)),"Bundles",IF(ISNUMBER(SEARCH("Merchant",C32)),"Merchant Payment",IF(ISNUMBER(SEARCH("Offnet C2B",C32)),"Merchant Payment",IF(ISNUMBER(SEARCH("Offnet B2C",C32)),"Merchant Payment",IF(ISNUMBER(SEARCH("Customer Payment to Small",C32)),"Merchant Payment",IF(ISNUMBER(SEARCH("Payment to Small Business",C32)),"Merchant Payment",IF(ISNUMBER(SEARCH("Sent to",C32)),"Sent to Person",IF(ISNUMBER(SEARCH("Customer Transfer to",C32)),"Sent to Person",IF(ISNUMBER(SEARCH("Business Payment",C32)),"Money In",IF(ISNUMBER(SEARCH("Funds Received",C32)),"Money In",IF(ISNUMBER(SEARCH("Receive International",C32)),"Money In",IF(ISNUMBER(SEARCH("Send Money Reversal",C32)),"Money In",IF(ISNUMBER(SEARCH("Pay Utility Reversal",C32)),"Money In",IF(ISNUMBER(SEARCH("Customer Transfer",C32)),"Money In",IF(ISNUMBER(SEARCH("Ziidi",C32)),"Investment",IF(ISNUMBER(SEARCH("Nabo",C32)),"Investment",IF(ISNUMBER(SEARCH("Paybill Online",C32)),"Pay Bill",IF(ISNUMBER(SEARCH("Pay Bill",C32)),"Pay Bill",IF(ISNUMBER(SEARCH("Spotify",C32)),"Pay Bill",IF(ISNUMBER(SEARCH("M-Shwari",C32)),"Mshwari",IF(ISNUMBER(SEARCH("Mshwari",C32)),"Mshwari",IF(ISNUMBER(SEARCH("Withdrawal charge",C32)),"Fees",IF(ISNUMBER(SEARCH("Customer Withdrawal",C32)),"Fees",IF(ISNUMBER(SEARCH("charge",C32)),"Fees","Other"))))))))))))))))))))))))) -> Bundles | R32: =TEXT(B2,"MMM YYYY") -> Jan 2026
A33: UAHA940KSY | B33: 2026-01-17 16:37:19 | C33: Customer Bundle Purchase to | D33: Completed | F33: 10 | G33: 1780 | L33: =IF(ISNUMBER(SEARCH("Bundle",C33)),"Bundles",IF(ISNUMBER(SEARCH("Airtime",C33)),"Bundles",IF(ISNUMBER(SEARCH("Merchant",C33)),"Merchant Payment",IF(ISNUMBER(SEARCH("Offnet C2B",C33)),"Merchant Payment",IF(ISNUMBER(SEARCH("Offnet B2C",C33)),"Merchant Payment",IF(ISNUMBER(SEARCH("Customer Payment to Small",C33)),"Merchant Payment",IF(ISNUMBER(SEARCH("Payment to Small Business",C33)),"Merchant Payment",IF(ISNUMBER(SEARCH("Sent to",C33)),"Sent to Person",IF(ISNUMBER(SEARCH("Customer Transfer to",C33)),"Sent to Person",IF(ISNUMBER(SEARCH("Business Payment",C33)),"Money In",IF(ISNUMBER(SEARCH("Funds Received",C33)),"Money In",IF(ISNUMBER(SEARCH("Receive International",C33)),"Money In",IF(ISNUMBER(SEARCH("Send Money Reversal",C33)),"Money In",IF(ISNUMBER(SEARCH("Pay Utility Reversal",C33)),"Money In",IF(ISNUMBER(SEARCH("Customer Transfer",C33)),"Money In",IF(ISNUMBER(SEARCH("Ziidi",C33)),"Investment",IF(ISNUMBER(SEARCH("Nabo",C33)),"Investment",IF(ISNUMBER(SEARCH("Paybill Online",C33)),"Pay Bill",IF(ISNUMBER(SEARCH("Pay Bill",C33)),"Pay Bill",IF(ISNUMBER(SEARCH("Spotify",C33)),"Pay Bill",IF(ISNUMBER(SEARCH("M-Shwari",C33)),"Mshwari",IF(ISNUMBER(SEARCH("Mshwari",C33)),"Mshwari",IF(ISNUMBER(SEARCH("Withdrawal charge",C33)),"Fees",IF(ISNUMBER(SEARCH("Customer Withdrawal",C33)),"Fees",IF(ISNUMBER(SEARCH("charge",C33)),"Fees","Other"))))))))))))))))))))))))) -> Bundles | R33: =TEXT(B33,"MMM YYYY") -> Jan 2026
A34: UAHA94206V | B34: 2026-01-17 21:18:00 | C34: Customer Bundle Purchase to | D34: Completed | F34: 10 | G34: 1770 | L34: =IF(ISNUMBER(SEARCH("Bundle",C34)),"Bundles",IF(ISNUMBER(SEARCH("Airtime",C34)),"Bundles",IF(ISNUMBER(SEARCH("Merchant",C34)),"Merchant Payment",IF(ISNUMBER(SEARCH("Offnet C2B",C34)),"Merchant Payment",IF(ISNUMBER(SEARCH("Offnet B2C",C34)),"Merchant Payment",IF(ISNUMBER(SEARCH("Customer Payment to Small",C34)),"Merchant Payment",IF(ISNUMBER(SEARCH("Payment to Small Business",C34)),"Merchant Payment",IF(ISNUMBER(SEARCH("Sent to",C34)),"Sent to Person",IF(ISNUMBER(SEARCH("Customer Transfer to",C34)),"Sent to Person",IF(ISNUMBER(SEARCH("Business Payment",C34)),"Money In",IF(ISNUMBER(SEARCH("Funds Received",C34)),"Money In",IF(ISNUMBER(SEARCH("Receive International",C34)),"Money In",IF(ISNUMBER(SEARCH("Send Money Reversal",C34)),"Money In",IF(ISNUMBER(SEARCH("Pay Utility Reversal",C34)),"Money In",IF(ISNUMBER(SEARCH("Customer Transfer",C34)),"Money In",IF(ISNUMBER(SEARCH("Ziidi",C34)),"Investment",IF(ISNUMBER(SEARCH("Nabo",C34)),"Investment",IF(ISNUMBER(SEARCH("Paybill Online",C34)),"Pay Bill",IF(ISNUMBER(SEARCH("Pay Bill",C34)),"Pay Bill",IF(ISNUMBER(SEARCH("Spotify",C34)),"Pay Bill",IF(ISNUMBER(SEARCH("M-Shwari",C34)),"Mshwari",IF(ISNUMBER(SEARCH("Mshwari",C34)),"Mshwari",IF(ISNUMBER(SEARCH("Withdrawal charge",C34)),"Fees",IF(ISNUMBER(SEARCH("Customer Withdrawal",C34)),"Fees",IF(ISNUMBER(SEARCH("charge",C34)),"Fees","Other"))))))))))))))))))))))))) -> Bundles | R34: =TEXT(B34,"MMM YYYY") -> Jan 2026
A35: UAIA94510U | B35: 2026-01-18 21:26:13 | C35: Customer Bundle Purchase to | D35: Completed | F35: 10 | G35: 1760 | L35: =IF(ISNUMBER(SEARCH("Bundle",C35)),"Bundles",IF(ISNUMBER(SEARCH("Airtime",C35)),"Bundles",IF(ISNUMBER(SEARCH("Merchant",C35)),"Merchant Payment",IF(ISNUMBER(SEARCH("Offnet C2B",C35)),"Merchant Payment",IF(ISNUMBER(SEARCH("Offnet B2C",C35)),"Merchant Payment",IF(ISNUMBER(SEARCH("Customer Payment to Small",C35)),"Merchant Payment",IF(ISNUMBER(SEARCH("Payment to Small Business",C35)),"Merchant Payment",IF(ISNUMBER(SEARCH("Sent to",C35)),"Sent to Person",IF(ISNUMBER(SEARCH("Customer Transfer to",C35)),"Sent to Person",IF(ISNUMBER(SEARCH("Business Payment",C35)),"Money In",IF(ISNUMBER(SEARCH("Funds Received",C35)),"Money In",IF(ISNUMBER(SEARCH("Receive International",C35)),"Money In",IF(ISNUMBER(SEARCH("Send Money Reversal",C35)),"Money In",IF(ISNUMBER(SEARCH("Pay Utility Reversal",C35)),"Money In",IF(ISNUMBER(SEARCH("Customer Transfer",C35)),"Money In",IF(ISNUMBER(SEARCH("Ziidi",C35)),"Investment",IF(ISNUMBER(SEARCH("Nabo",C35)),"Investment",IF(ISNUMBER(SEARCH("Paybill Online",C35)),"Pay Bill",IF(ISNUMBER(SEARCH("Pay Bill",C35)),"Pay Bill",IF(ISNUMBER(SEARCH("Spotify",C35)),"Pay Bill",IF(ISNUMBER(SEARCH("M-Shwari",C35)),"Mshwari",IF(ISNUMBER(SEARCH("Mshwari",C35)),"Mshwari",IF(ISNUMBER(SEARCH("Withdrawal charge",C35)),"Fees",IF(ISNUMBER(SEARCH("Customer Withdrawal",C35)),"Fees",IF(ISNUMBER(SEARCH("charge",C35)),"Fees","Other"))))))))))))))))))))))))) -> Bundles | R35: =TEXT(B35,"MMM YYYY") -> Jan 2026
A36: UAIA9451BV | B36: 2026-01-18 21:44:57 | C36: Customer Bundle Purchase to | D36: Completed | F36: 10 | G36: 1750 | L36: =IF(ISNUMBER(SEARCH("Bundle",C36)),"Bundles",IF(ISNUMBER(SEARCH("Airtime",C36)),"Bundles",IF(ISNUMBER(SEARCH("Merchant",C36)),"Merchant Payment",IF(ISNUMBER(SEARCH("Offnet C2B",C36)),"Merchant Payment",IF(ISNUMBER(SEARCH("Offnet B2C",C36)),"Merchant Payment",IF(ISNUMBER(SEARCH("Customer Payment to Small",C36)),"Merchant Payment",IF(ISNUMBER(SEARCH("Payment to Small Business",C36)),"Merchant Payment",IF(ISNUMBER(SEARCH("Sent to",C36)),"Sent to Person",IF(ISNUMBER(SEARCH("Customer Transfer to",C36)),"Sent to Person",IF(ISNUMBER(SEARCH("Business Payment",C36)),"Money In",IF(ISNUMBER(SEARCH("Funds Received",C36)),"Money In",IF(ISNUMBER(SEARCH("Receive International",C36)),"Money In",IF(ISNUMBER(SEARCH("Send Money Reversal",C36)),"Money In",IF(ISNUMBER(SEARCH("Pay Utility Reversal",C36)),"Money In",IF(ISNUMBER(SEARCH("Customer Transfer",C36)),"Money In",IF(ISNUMBER(SEARCH("Ziidi",C36)),"Investment",IF(ISNUMBER(SEARCH("Nabo",C36)),"Investment",IF(ISNUMBER(SEARCH("Paybill Online",C36)),"Pay Bill",IF(ISNUMBER(SEARCH("Pay Bill",C36)),"Pay Bill",IF(ISNUMBER(SEARCH("Spotify",C36)),"Pay Bill",IF(ISNUMBER(SEARCH("M-Shwari",C36)),"Mshwari",IF(ISNUMBER(SEARCH("Mshwari",C36)),"Mshwari",IF(ISNUMBER(SEARCH("Withdrawal charge",C36)),"Fees",IF(ISNUMBER(SEARCH("Customer Withdrawal",C36)),"Fees",IF(ISNUMBER(SEARCH("charge",C36)),"Fees","Other"))))))))))))))))))))))))) -> Bundles | R36: =TEXT(B36,"MMM YYYY") -> Jan 2026
A37: UAJA945AIT | B37: 2026-01-19 03:09:39 | C37: Customer Bundle Purchase to | D37: Completed | F37: 30 | G37: 1720 | L37: =IF(ISNUMBER(SEARCH("Bundle",C37)),"Bundles",IF(ISNUMBER(SEARCH("Airtime",C37)),"Bundles",IF(ISNUMBER(SEARCH("Merchant",C37)),"Merchant Payment",IF(ISNUMBER(SEARCH("Offnet C2B",C37)),"Merchant Payment",IF(ISNUMBER(SEARCH("Offnet B2C",C37)),"Merchant Payment",IF(ISNUMBER(SEARCH("Customer Payment to Small",C37)),"Merchant Payment",IF(ISNUMBER(SEARCH("Payment to Small Business",C37)),"Merchant Payment",IF(ISNUMBER(SEARCH("Sent to",C37)),"Sent to Person",IF(ISNUMBER(SEARCH("Customer Transfer to",C37)),"Sent to Person",IF(ISNUMBER(SEARCH("Business Payment",C37)),"Money In",IF(ISNUMBER(SEARCH("Funds Received",C37)),"Money In",IF(ISNUMBER(SEARCH("Receive International",C37)),"Money In",IF(ISNUMBER(SEARCH("Send Money Reversal",C37)),"Money In",IF(ISNUMBER(SEARCH("Pay Utility Reversal",C37)),"Money In",IF(ISNUMBER(SEARCH("Customer Transfer",C37)),"Money In",IF(ISNUMBER(SEARCH("Ziidi",C37)),"Investment",IF(ISNUMBER(SEARCH("Nabo",C37)),"Investment",IF(ISNUMBER(SEARCH("Paybill Online",C37)),"Pay Bill",IF(ISNUMBER(SEARCH("Pay Bill",C37)),"Pay Bill",IF(ISNUMBER(SEARCH("Spotify",C37)),"Pay Bill",IF(ISNUMBER(SEARCH("M-Shwari",C37)),"Mshwari",IF(ISNUMBER(SEARCH("Mshwari",C37)),"Mshwari",IF(ISNUMBER(SEARCH("Withdrawal charge",C37)),"Fees",IF(ISNUMBER(SEARCH("Customer Withdrawal",C37)),"Fees",IF(ISNUMBER(SEARCH("charge",C37)),"Fees","Other"))))))))))))))))))))))))) -> Bundles | R37: =TEXT(B37,"MMM YYYY") -> Jan 2026
A38: UAJA946AB6 | B38: 2026-01-19 12:35:36 | C38: Customer Bundle Purchase to | D38: Completed | F38: 10 | G38: 1710 | L38: =IF(ISNUMBER(SEARCH("Bundle",C38)),"Bundles",IF(ISNUMBER(SEARCH("Airtime",C38)),"Bundles",IF(ISNUMBER(SEARCH("Merchant",C38)),"Merchant Payment",IF(ISNUMBER(SEARCH("Offnet C2B",C38)),"Merchant Payment",IF(ISNUMBER(SEARCH("Offnet B2C",C38)),"Merchant Payment",IF(ISNUMBER(SEARCH("Customer Payment to Small",C38)),"Merchant Payment",IF(ISNUMBER(SEARCH("Payment to Small Business",C38)),"Merchant Payment",IF(ISNUMBER(SEARCH("Sent to",C38)),"Sent to Person",IF(ISNUMBER(SEARCH("Customer Transfer to",C38)),"Sent to Person",IF(ISNUMBER(SEARCH("Business Payment",C38)),"Money In",IF(ISNUMBER(SEARCH("Funds Received",C38)),"Money In",IF(ISNUMBER(SEARCH("Receive International",C38)),"Money In",IF(ISNUMBER(SEARCH("Send Money Reversal",C38)),"Money In",IF(ISNUMBER(SEARCH("Pay Utility Reversal",C38)),"Money In",IF(ISNUMBER(SEARCH("Customer Transfer",C38)),"Money In",IF(ISNUMBER(SEARCH("Ziidi",C38)),"Investment",IF(ISNUMBER(SEARCH("Nabo",C38)),"Investment",IF(ISNUMBER(SEARCH("Paybill Online",C38)),"Pay Bill",IF(ISNUMBER(SEARCH("Pay Bill",C38)),"Pay Bill",IF(ISNUMBER(SEARCH("Spotify",C38)),"Pay Bill",IF(ISNUMBER(SEARCH("M-Shwari",C38)),"Mshwari",IF(ISNUMBER(SEARCH("Mshwari",C38)),"Mshwari",IF(ISNUMBER(SEARCH("Withdrawal charge",C38)),"Fees",IF(ISNUMBER(SEARCH("Customer Withdrawal",C38)),"Fees",IF(ISNUMBER(SEARCH("charge",C38)),"Fees","Other"))))))))))))))))))))))))) -> Bundles | R38: =TEXT(B38,"MMM YYYY") -> Jan 2026
